Workbook

Sheet 0-Instructions
A2: Subcontractor Invoice Instructions
A4: Please send monthly invoices to:
A5: Brown and Caldwell
A6: Attn: NY Payables
A7: NYPayables@brwncald.com
A9: Invoices shall include the following documentation:
A11: 1 | B11: Invoice Cover Sheet: The invoice cover sheet is a summary of what is being submitted. Examples: Outline of task and/or subtask activities completed during the billing period or the Subcontractor's invoice breakdown of task and/or subtask.
A12: 2 | B12: Invoice Work Summary Sheet (Tab 2): The Work Summary includes a description of the Scope of Services per task(s) and will also include a narrative of what work was completed during the billing period. If a section of the Work Summary does not apply to the invoice, indicate by inserting N/A in that section.
A13: 3 | B13: Summary Billing Report (Tab 3): If an Invoice Cover Sheet contains tracking the following on a subtask level, these subtasks do not need to be included/inserted again into the Summary Billing Report (e.g., rows 38-39):
C14: 1) Total billed previously
C15: 2) Amount billed this period
C16: 3) Total billed to dated
C17: 4) Subtask maximum
C18: 5) Remaining Balance
A19: 4 | B19: Cost-Plus Task(s): Include the following documentation along with Nos 1, 2, and 3.
B20: a. Labor Summary (Tab 4a)
B21: b. 40-Hour Employee Signed Timesheets or electronic 40-Hour Timesheet on a weekly or bi-weekly basis.
C22: 1) Identify the subtask number(s) associated with time logged toward project.
B23: c. Travel Authorization: A form must be requested from Project Manager for each staff member.
C24: 1) Travel to the Client must be approved at least 5 days in advance by Brown and Caldwell and signed by DEP prior to travel occuring. Submit completed Travel Authoization forms to NYPayables@brwncald.com.
B25: d. Proof of all travel expenses
C26: 1) All other direct costs (ODC) receipts must have a date and time stamp, be itemized, show the vendor name and location, and is legible. Charges for direct reimbursable expenses and ODC shall be at actual cost subject to NYC Directive 6.
C27: 2) Identify the task number(s) associated with the expense.
C28: 3) Blackout/redact any excess charges not being billed toward the Project.
C29: 4) Identify which receipts are breakfast, lunch, and dinner.
C30: 5) Alcohol is not reimbursable to the client
C31: 6) Travel arrangements must be booked using the lowest cost economy or coach rates available. Incremental costs of upgrades are not reimburseable.
C32: 7) Miscellaneous Expenses: Entertainment, personal expenses, and flight insurance will not be reimbursed including car washes, laundry & dry cleaning, taxi & travel cost during non-working hours, and other similar miscellaneous non-work-related expenses.
C33: 8) Mileage Log (Tab 4b) Effective January 1, 2020 IRS approved mileage rate is $0.575 per mile. Transportation costs for travel between staff's residence and any Primary Workstation are not reimburseable.
A34: 5 | B34: Lump Sum Task(s): Include the additional documentation along with Nos 1, 2, and 3.
B35: b. Lump Sum Deliverable Sheet (Tab 5)
C36: 1) Include task(s) completed during the billing period.
A38: Please note:
A39: 1 | B39: By the 7th of each month, submit an invoice for work completed during the preceding month.
A40: 2 | B40: Refer to Prime Agreement for Subcontractor's overhead rates, profit percentages and rates for anticipated staff.
A41: 3 | B41: In the event a new DEP Audited Overhead Rate is received, please forward the Rate Letter to NYPayables@brwncald.com.
A42: 4 | B42: Each additional staff member not listed on the Project Prime Agreement must complete a Staff Addition Request to BC and approved by DEP prior to working on the project. Failure to obtain preapprovals may result in payments being delayed and/or portions of payments being Line H or permanently withheld from payment, Line A by DEP. Staff Addition Requests can be written via email or on company letterhead detailing each member's full name, title, project role, hourly unloaded rate, and if he/she/they are a new addition to the project or replacing a specific staff member already on the Project, and resumes for staff listed.
A43: 5 | B43: Cost amounts shall be shown to two (2) decimal places (i.e., cents). Do not round to the whole dollar.
A44: 6 | B44: Precise statement of work performed during billing period (Work Summary) must be with your invoice.
A45: 7 | B45: Appropriate person must certify all invoices with the Contractor's Task Manager. All signatures must be legible.
...

Sheet 1-Invoice Cover Sheet
A4: ='3-Summary Billing Report'!A4 -> 15 Bonita Vista Road, Mount Vernon, NY 10552
A6: Invoice | E6: Date: | F6: ='3-Summary Billing Report'!I3 -> 46204
A8: NYPayables
A9: Brown and Caldwell
A10: 1350 Broadway
A11: Suite 2000
A12: New York, NY 10018
A14: 5 | B14: Master Planning for Jamaica Bay Wastewater Resource Recovery Facility Consolidation
A15: Invoice Period: | B15: 06/01/2026-06/30/2026
A17: Subcontract Maximum | B17: =E63 -> 47490
A18: Amendment One | B18: 0
A20: Task & Description | B20: Total Billed Previously | C20: This Invoice | D20: Total Billed to Date | E20: Subcontract Max | F20: Balance Remaining
A21: Task 1 - Project Management | E21: =SUM(E22:E24) -> 0
B22: 0 | C22: 0 | D22: =B22+C22 -> 0 | E22: 0 | F22: =E22-D22 -> 0
B23: 0 | C23: 0 | D23: =B23+C23 -> 0 | E23: 0 | F23: =E23-D23 -> 0
B24: 0 | C24: 0 | D24: =B24+C24 -> 0 | E24: 0 | F24: =E24-D24 -> 0
A26: Task 2 - Site Survey and Information Collection | B26: =SUM(B27:B35) -> 8206.69 | C26: =SUM(C27:C35) -> 11808.95 | D26: =SUM(D27:D35) -> 20015.64 | E26: =SUM(E27:E35) -> 47490 | F26: =SUM(F27:F35) -> 27474.36
A27: 2.01.003: Existing Data Collection Memorandum and Gap Analysis | B27: =Previous!J2 -> 8206.69 | C27: 996.38 | D27: =B27+C27 -> 9203.07 | E27: 9375 | F27: =E27-D27 -> 171.93
A28: 2.05.001: Workshop | B28: 0 | D28: =B28+C28 -> 9318.3 | E28: 9375 | F28: =E28-D28 -> 56.7
A29: 2.05.002: Regulatory Futures Report Support | B29: 0 | D29: =B29+C29 -> 1494.27 | E29: 5830 | F29: =E29-D29 -> 4335.73
A30: 2.06: Existing Conditions Assessment Report | B30: 0 | C30: 0 | D30: =B30+C30 -> 0 | E30: 22910 | F30: =E30-D30 -> 22910
B31: 0 | C31: 0 | D31: =B31+C31 -> 0 | E31: 0 | F31: =E31-D31 -> 0
B32: 0 | C32: 0 | D32: =B32+C32 -> 0 | E32: 0 | F32: =E32-D32 -> 0
B33: 0 | C33: 0 | D33: =B33+C33 -> 0 | E33: 0 | F33: =E33-D33 -> 0
B34: 0 | C34: 0 | D34: =B34+C34 -> 0 | E34: 0 | F34: =E34-D34 -> 0
B35: 0 | C35: 0 | D35: =B35+C35 -> 0 | E35: 0 | F35: =E35-D35 -> 0
A37: Task 3 - Alternatives Evaluation | E37: =SUM(E38:E40) -> 0
B38: 0 | C38: 0 | D38: =B38+C38 -> 0 | E38: 0 | F38: =E38-D38 -> 0
B39: 0 | C39: 0 | D39: =B39+C39 -> 0 | E39: 0 | F39: =E39-D39 -> 0
B40: 0 | C40: 0 | D40: =B40+C40 -> 0 | E40: 0 | F40: =E40-D40 -> 0
A42: Task 4 - Concept Design | E42: =SUM(E43:E45) -> 0
B43: 0 | C43: 0 | D43: =B43+C43 -> 0 | E43: 0 | F43: =E43-D43 -> 0
B44: 0 | C44: 0 | D44: =B44+C44 -> 0 | E44: 0 | F44: =E44-D44 -> 0
B45: 0 | C45: 0 | D45: =B45+C45 -> 0 | E45: 0 | F45: =E45-D45 -> 0
A47: Task 5 - Cost Estimating | E47: =SUM(E48:E50) -> 0
B48: 0 | C48: 0 | D48: =B48+C48 -> 0 | E48: 0 | F48: =E48-D48 -> 0
B49: 0 | C49: 0 | D49: =B49+C49 -> 0 | E49: 0 | F49: =E49-D49 -> 0
B50: 0 | C50: 0 | D50: =B50+C50 -> 0 | E50: 0 | F50: =E50-D50 -> 0
A52: Task 6 - Master Plan and Delivery Strategy | E52: =SUM(E53:E55) -> 0
B53: 0 | C53: 0 | D53: =B53+C53 -> 0 | E53: 0 | F53: =E53-D53 -> 0
...

Sheet Sheet1
A1: BWT 1608-Jobcon
A2: Client | B2: Service/Note | C2: Team | D2: Status | E2: Total Hours | F2: Total Costs
C3: Member/Date
A4: Brown and Caldwell Brown and Caldwell | B4: Task 1-Memo Support | C4: Ailsa Welch | D4: Billed | E4: 2h 00m | F4: $291.56 USD
B5: Citation list review, formatting, editing, completion and upload to shared drive. | C5: 46203
A6: Brown and Caldwell Brown and Caldwell | B6: Task 1-Memo Support | C6: Ailsa Welch | D6: Billed | E6: 4h 00m | F6: $583.12 USD
B7: Internal meeting, client meeting. Up-loading of documents to the shared drive. Creation of deck for client meeting. | C7: 46197
A8: Brown and Caldwell Brown and Caldwell | B8: Task 1-Memo Support | C8: Bertrand Byrne | D8: Billed | E8: 2h 00m | F8: $369.24 USD
B9: Prepare monitoring location data and attend meeting | C9: 46197
A10: Brown and Caldwell Brown and Caldwell | B10: No Service | C10: Robert Svadlenka | D10: Billed | E10: 5h 00m | F10: $569.85 USD
B11: Revise map exhibits and supporting spatial databases in accordance with project team requests; prepare captions to support exceptions in specific exhibits; attend team meeting | C11: 46197
A12: Brown and Caldwell Brown and Caldwell | B12: Task 1-Memo Support | C12: Bertrand Byrne | D12: Billed | E12: 2h 00m | F12: $369.24 USD
B13: Update water quality summary table | C13: 46196
A14: Brown and Caldwell Brown and Caldwell | B14: No Service | C14: Robert Svadlenka | D14: Billed | E14: 3h 00m | F14: $341.91 USD
B15: Revise map exhibits and supporting spatial databases in accordance with project team requests; prepare captions to support exceptions in specific exhibits. | C15: 46196
A16: Brown and Caldwell Brown and Caldwell | B16: Task 1-Memo Support | C16: Ailsa Welch | D16: Billed | E16: 2h 00m | F16: $291.56 USD
B17: Located and review status of timeline per request. Meeting with internal team to assess outstanding. Items. Review work done. | C17: 46196
A18: Brown and Caldwell Brown and Caldwell | B18: No Service | C18: Robert Svadlenka | D18: Billed | E18: 4h 00m | F18: $455.88 USD
B19: Revise map exhibits and supporting spatial databases in accordance with project team requests. | C19: 46195
A20: Brown and Caldwell Brown and Caldwell | B20: Task 1-Memo Support | C20: Ailsa Welch | D20: Billed | E20: 2h 00m | F20: $291.56 USD
B21: Sourcing and collation of timeline data, diagrams and relevant files. | C21: 46195
A22: Brown and Caldwell Brown and Caldwell | B22: No Service | C22: Robert Svadlenka | D22: Billed | E22: 3h 00m | F22: $341.91 USD
B23: Edit spatial databases and map exhibits to comply with team requests for revisions. | C23: 46192
A24: Brown and Caldwell Brown and Caldwell | B24: No Service | C24: Robert Svadlenka | D24: Billed | E24: 3h 00m | F24: $341.91 USD
B25: Edit spatial databases and map exhibits to comply with team requests for revisions. | C25: 46191
A26: Brown and Caldwell Brown and Caldwell | B26: Task 1-Memo Support | C26: Bertrand Byrne | D26: Billed | E26: 2h 00m | F26: $369.24 USD
B27: Review updated figures + Meeting attendance | C27: 46190
A28: Brown and Caldwell Brown and Caldwell | B28: Task 1-Memo Support | C28: Ailsa Welch | D28: Billed | E28: 3h 00m | F28: $437.34 USD
B29: Meeting prep, internal meeting to coordinate finalization of materials. Attendance of client team meeting. | C29: 46190
A30: Brown and Caldwell Brown and Caldwell | B30: No Service | C30: Robert Svadlenka | D30: Billed | E30: 2h 00m | F30: $227.94 USD
B31: Attend team meeting and research/download additional spatial data set for exhibits. | C31: 46190
A32: Brown and Caldwell Brown and Caldwell | B32: Task 1-Memo Support | C32: Bertrand Byrne | D32: Billed | E32: 2h 00m | F32: $369.24 USD
B33: Review updated figures & meeting prep | C33: 46189
A34: Brown and Caldwell Brown and Caldwell | B34: Task 1-Memo Support | C34: Bertrand Byrne | D34: Billed | E34: 3h 00m | F34: $553.86 USD
B35: Review updated figures | C35: 46185
A36: Brown and Caldwell Brown and Caldwell | B36: No Service | C36: Robert Svadlenka | D36: Billed | E36: 3h 00m | F36: $341.91 USD
B37: Finalize edits to preliminary planning document and coordinate with team on all requested/required revisions. | C37: 46185
A38: Brown and Caldwell Brown and Caldwell | B38: Task 1-Memo Support | C38: Ailsa Welch | D38: Billed | E38: 2h 00m | F38: $291.56 USD
B39: Preparation for meeting, creation of slide deck, upload of documentation to shared drive. Internal meetings to compile documentation and update status. | C39: 46185
A40: Brown and Caldwell Brown and Caldwell | B40: No Service | C40: Robert Svadlenka | D40: Billed | E40: 5h 00m | F40: $569.85 USD
...

Sheet Previous
F1: May | G1: June | H1: July | I1: August
E2: 2.01.003: Existing Data Collection Memorandum and Gap Analysis | F2: 8206.69 | J2: =SUM(F2:I2) -> 8206.69
E3: 2.05.001: Workshop | J3: =SUM(F3:I3) -> 0
E4: 2.05.002: Regulatory Futures Report Support | J4: =SUM(F4:I4) -> 0
E5: 2.06: Existing Conditions Assessment Report | J5: =SUM(F5:I5) -> 0
F6: =SUM(F2:F5) -> 8206.69 | G6: =SUM(G2:G5) -> 0 | H6: =SUM(H2:H5) -> 0 | I6: =SUM(I2:I5) -> 0 | J6: =SUM(F6:I6) -> 8206.69

Sheet 2-Work Summary
B1: Work Summary
B2: Contract Name: | C2: BWT-1608-JBCON
B3: PIN: | C3: 826251608JBCON
B4: Contract Reg. No.: | C4: CTI 826 20268804134
B5: BC Project Nos.: | C5: 203434
B6: Assignment: | C6: Master Planning for Jamaica Bay Wastewater Resource Recovery Facility Consolidation
B7: Firm: | C7: Aquatech Engineering P.C.
B8: Invoice No.: | C8: BACAQ0002
B9: Invoice Period: | C9: ='1-Invoice Cover Sheet'!B15 -> 06/01/2026-06/30/2026
B12: Phase and Task(s):
B13: Major activities completed and deliverables submitted for the reporting period.
B14: Provided technical memorandum support, including QA/QC, editing, formatting, citation review, and preparation of supporting documentation; coordinated internal and client meetings; prepared meeting materials, presentations, action trackers, and project documentation; revised report maps, exhibits, captions, and supporting GIS databases; prepared and updated water quality monitoring location summaries and associated tables; researched and compiled supporting project information; incorporated project team comments into technical documents and mapping products; and supported ongoing project coordination and planning activities.
B15: Task 2.1 – Collection of Existing Information
B16: Reviewed existing project information, planning documents, technical memorandum content, and supporting reference materials. Performed QA/QC, editing, formatting, and citation review of the draft technical memorandum. Compiled, reviewed, and updated water quality monitoring location data and summary tables. Researched, compiled, and organized supporting project information, timeline data, figures, and reference materials. Revised report figures, map exhibits, captions, and supporting GIS/spatial databases in response to project team comments. Prepared meeting materials, presentation decks, action trackers, and project documentation. Participated in internal coordination meetings and client meetings to review progress, coordinate revisions, and support ongoing project development. Uploaded, organized, and maintained project documentation on the shared project workspace.
B19: Task 2.5 – Regulatory Futures
B20: Supported technical memorandum development through QA/QC, editing, formatting, and citation review. Participated in coordination meetings to discuss project progress, planning considerations, and future technical work. Prepared meeting materials, presentation decks, and action tracking documentation to support project coordination.
B23: Task 2.6 – Existing Conditions Assessment Report
B24: Revised report figures, map exhibits, captions, and supporting GIS/spatial databases in response to project team comments. Incorporated review comments into mapping products and supporting technical documentation. Updated presentation materials and coordinated revisions to support development of Existing Conditions Assessment report deliverables.

Sheet 3-Summary Billing Report
A1: Summary Billing Report
A3: Aquatech Engineering P.C. | H3: Date: | I3: 46204
A4: 15 Bonita Vista Road, Mount Vernon, NY 10552
A10: Attention: | B10: NYPayables
B11: Brown and Caldwell
B12: 1350 Broadway
B13: Suite 2000
B14: New York, NY 10018
A18: Master Planning for Jamaica Bay Wastewater Resource Recovery Facility Consolidation
A21: Contract: | C21: ='2-Work Summary'!C2 -> BWT-1608-JBCON | H21: BC Project No: | I21: ='2-Work Summary'!C5 -> 203434
A22: Contract Registration No.: | C22: ='2-Work Summary'!C4 -> CTI 826 20268804134 | G22: BC PO No.: | I22: 44495
A23: Invoice No.: | C23: ='2-Work Summary'!C8 -> BACAQ0002 | G23: Subcontractor Project No.: | I23: 0010052026
A26: For Professional Engineering Services
A27: For the invoice period of | D27: 46143 | E27: to | F27: 46173
B29: This Invoice: | E29: =E47 -> 11808.95
D32: Total Billed | E32: This | F32: Total Billed | G32: Subcontract | H32: Balance | I32: % Completed | J32: % Complete
A33: Contract Summary By Task | D33: Previously | E33: Invoice | F33: To Date | G33: Maximum | H33: Remaining | I33: This Payment | J33: to Date
A36: 1 - Project Management | D36: 0 | E36: 0 | F36: 0 | G36: 0 | H36: =G36-F36 -> 0 | I36: =E36/G36 -> #DIV/0! | J36: =F36/G36 -> #DIV/0!
A37: 2 - Site Survey and Information Collection | D37: ='1-Invoice Cover Sheet'!B26 -> 8206.69 | E37: ='1-Invoice Cover Sheet'!C26 -> 11808.95 | F37: ='1-Invoice Cover Sheet'!D26 -> 20015.64 | G37: ='1-Invoice Cover Sheet'!E26 -> 47490 | H37: =G37-F37 -> 27474.36 | I37: =E37/G37 -> 0.24866182 | J37: =F37/G37 -> 0.42147063
A38: 3 - Alternatives Evaluation | D38: 0 | E38: 0 | F38: 0 | G38: 0 | H38: =G38-F38 -> 0 | I38: =E38/G38 -> #DIV/0! | J38: =F38/G38 -> #DIV/0!
A39: 4 - Concept Design | D39: 0 | E39: 0 | F39: 0 | G39: 0 | H39: =G39-F39 -> 0 | I39: =E39/G39 -> #DIV/0! | J39: =F39/G39 -> #DIV/0!
A40: 5 - Cost Estimating | D40: 0 | E40: 0 | F40: 0 | G40: 0 | H40: =G40-F40 -> 0 | I40: =E40/G40 -> #DIV/0! | J40: =F40/G40 -> #DIV/0!
A41: 6 - Master Plan and Delivery Strategy | D41: 0 | E41: 0 | F41: 0 | G41: 0 | H41: =G41-F41 -> 0 | I41: =E41/G41 -> #DIV/0! | J41: =F41/G41 -> #DIV/0!
A42: 7 - Outreach and Coordination | D42: 0 | E42: 0 | F42: =D42+E42 -> 0 | G42: 0 | H42: =G42-F42 -> 0 | I42: =E42/G42 -> #DIV/0! | J42: =F42/G42 -> #DIV/0!
C43: Total | D43: =SUM(D36:D42) -> 8206.69 | E43: =SUM(E36:E42) -> 11808.95 | F43: =SUM(F36:F42) -> 20015.64 | G43: =SUM(G36:G42) -> 47490 | H43: =SUM(H36:H42) -> 27474.36 | I43: =E43/G43 -> 0.24866182 | J43: =F43/G43 -> 0.42147063
A47: Total (Allocated) | D47: =D43 -> 8206.69 | E47: =E43 -> 11808.95 | F47: =F43 -> 20015.64 | G47: =G43 -> 47490 | H47: =H43 -> 27474.36 | I47: =I43 -> 0.24866182 | J47: =J43 -> 0.42147063
A50: I hereby certify that all labor charges in this invoice are legally and legitimately charged to this Contract in accordance
A51: with the terms and conditions of the Contract.
D56: Subcontractor Task Manager | I56: Date
D60: BC Deputy Task Manager | I60: Date

Sheet 4a-Labor Summary
A1: Labor Summary
A2: Contract Name: | B2: ='2-Work Summary'!C2 -> BWT-1608-JBCON
A3: PIN: | B3: ='2-Work Summary'!C3 -> 826251608JBCON
A4: Contract Reg. No.: | B4: ='2-Work Summary'!C4 -> CTI 826 20268804134
A5: BC Project Nos.: | B5: ='2-Work Summary'!C5 -> 203434
A6: Assignment: | B6: ='2-Work Summary'!C6 -> Master Planning for Jamaica Bay Wastewater Resource Recovery Facility Consolidation
A7: Firm: | B7: ='2-Work Summary'!C7 -> Aquatech Engineering P.C.
A8: Invoice No.: | B8: ='2-Work Summary'!C8 -> BACAQ0002
A9: Invoice Period: | B9: ='2-Work Summary'!C9 -> 06/01/2026-06/30/2026
A11: Labor Summary
A12: Name | B12: Position | C12: Hourly Rate | D12: Hours Billed | E12: Total Direct Labor
A14: Gilliam, Zachary | B14: Data Analyst / Modeler | C14: 52.26 | D14: 0 | E14: =ROUND(PRODUCT(C14,D14),2) -> 0
A15: Hodge, Stacey | B15: Senior Engineer | C15: 51.64 | D15: 0 | E15: =ROUND(PRODUCT(C15,D15),2) -> 0
A16: Svadlenka, Robert | B16: Senior Engineer / GIS | C16: 61.5 | D16: 38 | E16: =ROUND(PRODUCT(C16,D16),2) -> 2337
A17: Wang, Roger | B17: Senior Engineer | C17: 90 | D17: 0 | E17: =ROUND(PRODUCT(C17,D17),2) -> 0
A18: Welch, Alisa | B18: Project Manager, Data Specialist, Reg Lead | C18: 75 | D18: 18 | E18: =ROUND(PRODUCT(C18,D18),2) -> 1350
A19: TOTALS | D19: =SUM(D13:D18) -> 56 | E19: =SUM(E13:E18) -> 3687
A20: TOTAL OVERHEAD (DIRECT LABOR X OVERHEAD RATE) | E20: 2.14
A22: SUBTOTAL | E22: =ROUND(PRODUCT(E19:E21),2) -> 7890.18
A23: FEE FOR PROFIT (10%) | E23: =E22*0.1 -> 789.018
A24: Bryne, Bertrand | B24: Engineering Water Resource Lead/Senior Engineer | C24: 97.5 | D24: 15 | E24: =ROUND(PRODUCT(C24,D24),2) -> 1462.5
A25: TOTAL OVERHEAD (DIRECT LABOR X OVERHEAD RATE) | E25: 2.14
A27: SUBTOTAL | E27: =ROUND(PRODUCT(E24:E26),2) -> 3129.75
A28: TOTAL LABOR COST THIS INVOICE (FEE PLUS SUBTOTAL | E28: =ROUND(SUM(E22:E23,E27),2) -> 11808.95
A29: Lump Sum Billing | E29: 0
A30: ODCs | E30: 0
A31: GRAND TOTAL | E31: =ROUND(SUM(E28:E30),2) -> 11808.95
E32: =SUM('1-Invoice Cover Sheet'!E27-'1-Invoice Cover Sheet'!B27) -> 1168.31
E33: =SUM(E31-E32) -> 10640.64
D34: =SUM(E33-E34) -> 9375 | E34: =SUM(E33-9375) -> 1265.64

Sheet 4b-Mileage Log
C2: Brown and Caldwell
C3: Mileage Log
A4: Contract #: | B4: ='2-Work Summary'!C4 -> CTI 826 20268804134
A5: Firm: | B5: ARUP US, Inc
A6: Employee Name:
A8: Date of Travel | B8: Purpose of Trip | C8: Origin | D8: Desination | E8: Odometer | G8: Miles | H8: Mileage Rate | I8: Reimb. Amount | J8: Parking | K8: Tolls
E9: Beginning | F9: Ending
G11: =F11-E11 -> 0 | H11: 0.575 | I11: =G11*H11 -> 0 | M11: Be sure to update mileage rate to latest GSA rate.
G12: =F12-E12 -> 0 | H12: 0.575 | I12: =G12*H12 -> 0
G13: =F13-E13 -> 0 | H13: 0.575 | I13: =G13*H13 -> 0
G14: =F14-E14 -> 0 | H14: 0.575 | I14: =G14*H14 -> 0
G15: =F15-E15 -> 0 | H15: 0.575 | I15: =G15*H15 -> 0
G16: =F16-E16 -> 0 | H16: 0.575 | I16: =G16*H16 -> 0
G17: =F17-E17 -> 0 | H17: 0.575 | I17: =G17*H17 -> 0
G18: =F18-E18 -> 0 | H18: 0.575 | I18: =G18*H18 -> 0
G19: =F19-E19 -> 0 | H19: 0.575 | I19: =G19*H19 -> 0
G20: =F20-E20 -> 0 | H20: 0.575 | I20: =G20*H20 -> 0
I21: Total Reimb. Amount | J21: Total Parking | K21: Total Tolls
I23: =SUM(I11:I20) -> 0 | J23: =SUM(J11:J20) -> 0 | K23: =SUM(K11:K20) -> 0
I24: Total Trip Expense
A25: I hereby certify that the travel indicated above was a necessary and valid business expense. | I25: =I23+J23+K23 -> 0
A29: Employee Signature: | E29: Date:

Sheet 5-Lump Sum Deliverable
B1: Billing Detail - Lump Sum
B2: Contract Name: | C2: ='2-Work Summary'!C2 -> BWT-1608-JBCON
B3: PIN: | C3: ='2-Work Summary'!C3 -> 826251608JBCON
B4: Contract Reg. No.: | C4: ='2-Work Summary'!C4 -> CTI 826 20268804134
B5: BC Project Nos.: | C5: ='2-Work Summary'!C5 -> 203434
B6: Assignment: | C6: ='2-Work Summary'!C6 -> Master Planning for Jamaica Bay Wastewater Resource Recovery Facility Consolidation
B7: Firm: | C7: ARUP US, Inc
B8: Invoice No.:
B9: Invoice Period:
B11: Payment for Deliverable Invoiced
B12: Deliverable Name | C12: Payment Type (Acceptance/ Progress/Receipt) | E12: Date of Notice of Receipt or Acceptance (if relevant) | F12: Contract Item Number
B28: Subcontractor Task Manager | E28: Date
B31: BC Deputy Task Manager | E31: Date
